{"level":"ERROR","location":"[exception:108] fyers_logger","message":"HTTPSConnectionPool(host='api-t1.fyers.in', port=443): Max retries exceeded with url: /data/quotes?symbols=NSE%3AAPOLLOHOSP-EQ%2CNSE%3ABANKBARODA-EQ%2CNSE%3ABPCL-EQ%2CNSE%3ABRITANNIA-EQ%2CNSE%3ACANBK-EQ%2CNSE%3ADIVISLAB-EQ%2CNSE%3AGRASIM-EQ%2CNSE%3AHEROMOTOCO-EQ%2CNSE%3AHINDALCO-EQ%2CNSE%3AINDUSINDBK-EQ%2CNSE%3AIOC-EQ%2CNSE%3AJSWSTEEL-EQ%2CNSE%3AONGC-EQ%2CNSE%3ARELIANCE-EQ%2CNSE%3ASBILIFE-EQ%2CNSE%3ASBIN-EQ%2CNSE%3ASHREECEM-EQ%2CNSE%3ASHRIRAMFIN-EQ%2CNSE%3ATATACONSUM-EQ%2CNSE%3ATATAMOTORS-EQ (Caused by SSLError(SSLCertVerificationError(1, '[SSL: CERTIFICATE_VERIFY_FAILED] certificate verify failed: self signed certificate in certificate chain (_ssl.c:997)')))","timestamp":"2023-11-01 13:24:30,831+0530","service":"FyersDataSocket","exception":"Traceback (most recent call last):\n  File \"c:\\Users\\Sohum\\AppData\\Local\\Programs\\Python\\Python310\\lib\\site-packages\\websocket\\_app.py\", line 428, in setSock\n    dispatcher.read(self.sock.sock, read, check)\n  File \"c:\\Users\\Sohum\\AppData\\Local\\Programs\\Python\\Python310\\lib\\site-packages\\websocket\\_app.py\", line 99, in read\n    if not read_callback():\n  File \"c:\\Users\\Sohum\\AppData\\Local\\Programs\\Python\\Python310\\lib\\site-packages\\websocket\\_app.py\", line 442, in read\n    raise e\n  File \"c:\\Users\\Sohum\\AppData\\Local\\Programs\\Python\\Python310\\lib\\site-packages\\websocket\\_app.py\", line 437, in read\n    op_code, frame = self.sock.recv_data_frame(True)\n  File \"c:\\Users\\Sohum\\AppData\\Local\\Programs\\Python\\Python310\\lib\\site-packages\\websocket\\_core.py\", line 406, in recv_data_frame\n    frame = self.recv_frame()\n  File \"c:\\Users\\Sohum\\AppData\\Local\\Programs\\Python\\Python310\\lib\\site-packages\\websocket\\_core.py\", line 445, in recv_frame\n    return self.frame_buffer.recv_frame()\n  File \"c:\\Users\\Sohum\\AppData\\Local\\Programs\\Python\\Python310\\lib\\site-packages\\websocket\\_abnf.py\", line 338, in recv_frame\n    self.recv_header()\n  File \"c:\\Users\\Sohum\\AppData\\Local\\Programs\\Python\\Python310\\lib\\site-packages\\websocket\\_abnf.py\", line 294, in recv_header\n    header = self.recv_strict(2)\n  File \"c:\\Users\\Sohum\\AppData\\Local\\Programs\\Python\\Python310\\lib\\site-packages\\websocket\\_abnf.py\", line 373, in recv_strict\n    bytes_ = self.recv(min(16384, shortage))\n  File \"c:\\Users\\Sohum\\AppData\\Local\\Programs\\Python\\Python310\\lib\\site-packages\\websocket\\_core.py\", line 529, in _recv\n    return recv(self.sock, bufsize)\n  File \"c:\\Users\\Sohum\\AppData\\Local\\Programs\\Python\\Python310\\lib\\site-packages\\websocket\\_socket.py\", line 122, in recv\n    raise WebSocketConnectionClosedException(\nwebsocket._exceptions.WebSocketConnectionClosedException: Connection to remote host was lost.\n\nDuring handling of the above exception, another exception occurred:\n\nTraceback (most recent call last):\n  File \"c:\\Users\\Sohum\\AppData\\Local\\Programs\\Python\\Python310\\lib\\site-packages\\urllib3\\connectionpool.py\", line 703, in urlopen\n    httplib_response = self._make_request(\n  File \"c:\\Users\\Sohum\\AppData\\Local\\Programs\\Python\\Python310\\lib\\site-packages\\urllib3\\connectionpool.py\", line 386, in _make_request\n    self._validate_conn(conn)\n  File \"c:\\Users\\Sohum\\AppData\\Local\\Programs\\Python\\Python310\\lib\\site-packages\\urllib3\\connectionpool.py\", line 1042, in _validate_conn\n    conn.connect()\n  File \"c:\\Users\\Sohum\\AppData\\Local\\Programs\\Python\\Python310\\lib\\site-packages\\urllib3\\connection.py\", line 414, in connect\n    self.sock = ssl_wrap_socket(\n  File \"c:\\Users\\Sohum\\AppData\\Local\\Programs\\Python\\Python310\\lib\\site-packages\\urllib3\\util\\ssl_.py\", line 449, in ssl_wrap_socket\n    ssl_sock = _ssl_wrap_socket_impl(\n  File \"c:\\Users\\Sohum\\AppData\\Local\\Programs\\Python\\Python310\\lib\\site-packages\\urllib3\\util\\ssl_.py\", line 493, in _ssl_wrap_socket_impl\n    return ssl_context.wrap_socket(sock, server_hostname=server_hostname)\n  File \"c:\\Users\\Sohum\\AppData\\Local\\Programs\\Python\\Python310\\lib\\ssl.py\", line 513, in wrap_socket\n    return self.sslsocket_class._create(\n  File \"c:\\Users\\Sohum\\AppData\\Local\\Programs\\Python\\Python310\\lib\\ssl.py\", line 1071, in _create\n    self.do_handshake()\n  File \"c:\\Users\\Sohum\\AppData\\Local\\Programs\\Python\\Python310\\lib\\ssl.py\", line 1342, in do_handshake\n    self._sslobj.do_handshake()\nssl.SSLCertVerificationError: [SSL: CERTIFICATE_VERIFY_FAILED] certificate verify failed: self signed certificate in certificate chain (_ssl.c:997)\n\nDuring handling of the above exception, another exception occurred:\n\nTraceback (most recent call last):\n  File \"c:\\Users\\Sohum\\AppData\\Local\\Programs\\Python\\Python310\\lib\\site-packages\\requests\\adapters.py\", line 486, in send\n    resp = conn.urlopen(\n  File \"c:\\Users\\Sohum\\AppData\\Local\\Programs\\Python\\Python310\\lib\\site-packages\\urllib3\\connectionpool.py\", line 787, in urlopen\n    retries = retries.increment(\n  File \"c:\\Users\\Sohum\\AppData\\Local\\Programs\\Python\\Python310\\lib\\site-packages\\urllib3\\util\\retry.py\", line 592, in increment\n    raise MaxRetryError(_pool, url, error or ResponseError(cause))\nurllib3.exceptions.MaxRetryError: HTTPSConnectionPool(host='api-t1.fyers.in', port=443): Max retries exceeded with url: /data/quotes?symbols=NSE%3AAPOLLOHOSP-EQ%2CNSE%3ABANKBARODA-EQ%2CNSE%3ABPCL-EQ%2CNSE%3ABRITANNIA-EQ%2CNSE%3ACANBK-EQ%2CNSE%3ADIVISLAB-EQ%2CNSE%3AGRASIM-EQ%2CNSE%3AHEROMOTOCO-EQ%2CNSE%3AHINDALCO-EQ%2CNSE%3AINDUSINDBK-EQ%2CNSE%3AIOC-EQ%2CNSE%3AJSWSTEEL-EQ%2CNSE%3AONGC-EQ%2CNSE%3ARELIANCE-EQ%2CNSE%3ASBILIFE-EQ%2CNSE%3ASBIN-EQ%2CNSE%3ASHREECEM-EQ%2CNSE%3ASHRIRAMFIN-EQ%2CNSE%3ATATACONSUM-EQ%2CNSE%3ATATAMOTORS-EQ (Caused by SSLError(SSLCertVerificationError(1, '[SSL: CERTIFICATE_VERIFY_FAILED] certificate verify failed: self signed certificate in certificate chain (_ssl.c:997)')))\n\nDuring handling of the above exception, another exception occurred:\n\nTraceback (most recent call last):\n  File \"C:\\Users\\Sohum\\AppData\\Roaming\\Python\\Python310\\site-packages\\fyers_apiv3\\FyersWebsocket\\data_ws.py\", line 65, in symbol_to_hsmtoken\n    response = requests.get(\n  File \"c:\\Users\\Sohum\\AppData\\Local\\Programs\\Python\\Python310\\lib\\site-packages\\requests\\api.py\", line 73, in get\n    return request(\"get\", url, params=params, **kwargs)\n  File \"c:\\Users\\Sohum\\AppData\\Local\\Programs\\Python\\Python310\\lib\\site-packages\\requests\\api.py\", line 59, in request\n    return session.request(method=method, url=url, **kwargs)\n  File \"c:\\Users\\Sohum\\AppData\\Local\\Programs\\Python\\Python310\\lib\\site-packages\\requests\\sessions.py\", line 589, in request\n    resp = self.send(prep, **send_kwargs)\n  File \"c:\\Users\\Sohum\\AppData\\Local\\Programs\\Python\\Python310\\lib\\site-packages\\requests\\sessions.py\", line 703, in send\n    r = adapter.send(request, **kwargs)\n  File \"c:\\Users\\Sohum\\AppData\\Local\\Programs\\Python\\Python310\\lib\\site-packages\\requests\\adapters.py\", line 517, in send\n    raise SSLError(e, request=request)\nrequests.exceptions.SSLError: HTTPSConnectionPool(host='api-t1.fyers.in', port=443): Max retries exceeded with url: /data/quotes?symbols=NSE%3AAPOLLOHOSP-EQ%2CNSE%3ABANKBARODA-EQ%2CNSE%3ABPCL-EQ%2CNSE%3ABRITANNIA-EQ%2CNSE%3ACANBK-EQ%2CNSE%3ADIVISLAB-EQ%2CNSE%3AGRASIM-EQ%2CNSE%3AHEROMOTOCO-EQ%2CNSE%3AHINDALCO-EQ%2CNSE%3AINDUSINDBK-EQ%2CNSE%3AIOC-EQ%2CNSE%3AJSWSTEEL-EQ%2CNSE%3AONGC-EQ%2CNSE%3ARELIANCE-EQ%2CNSE%3ASBILIFE-EQ%2CNSE%3ASBIN-EQ%2CNSE%3ASHREECEM-EQ%2CNSE%3ASHRIRAMFIN-EQ%2CNSE%3ATATACONSUM-EQ%2CNSE%3ATATAMOTORS-EQ (Caused by SSLError(SSLCertVerificationError(1, '[SSL: CERTIFICATE_VERIFY_FAILED] certificate verify failed: self signed certificate in certificate chain (_ssl.c:997)')))","exception_name":"SSLError"}
{"level":"ERROR","location":"[exception:108] fyers_logger","message":"'NoneType' object is not subscriptable","timestamp":"2023-11-01 13:24:31,059+0530","service":"FyersDataSocket","exception":"Traceback (most recent call last):\n  File \"c:\\Users\\Sohum\\AppData\\Local\\Programs\\Python\\Python310\\lib\\site-packages\\websocket\\_app.py\", line 428, in setSock\n    dispatcher.read(self.sock.sock, read, check)\n  File \"c:\\Users\\Sohum\\AppData\\Local\\Programs\\Python\\Python310\\lib\\site-packages\\websocket\\_app.py\", line 99, in read\n    if not read_callback():\n  File \"c:\\Users\\Sohum\\AppData\\Local\\Programs\\Python\\Python310\\lib\\site-packages\\websocket\\_app.py\", line 442, in read\n    raise e\n  File \"c:\\Users\\Sohum\\AppData\\Local\\Programs\\Python\\Python310\\lib\\site-packages\\websocket\\_app.py\", line 437, in read\n    op_code, frame = self.sock.recv_data_frame(True)\n  File \"c:\\Users\\Sohum\\AppData\\Local\\Programs\\Python\\Python310\\lib\\site-packages\\websocket\\_core.py\", line 406, in recv_data_frame\n    frame = self.recv_frame()\n  File \"c:\\Users\\Sohum\\AppData\\Local\\Programs\\Python\\Python310\\lib\\site-packages\\websocket\\_core.py\", line 445, in recv_frame\n    return self.frame_buffer.recv_frame()\n  File \"c:\\Users\\Sohum\\AppData\\Local\\Programs\\Python\\Python310\\lib\\site-packages\\websocket\\_abnf.py\", line 338, in recv_frame\n    self.recv_header()\n  File \"c:\\Users\\Sohum\\AppData\\Local\\Programs\\Python\\Python310\\lib\\site-packages\\websocket\\_abnf.py\", line 294, in recv_header\n    header = self.recv_strict(2)\n  File \"c:\\Users\\Sohum\\AppData\\Local\\Programs\\Python\\Python310\\lib\\site-packages\\websocket\\_abnf.py\", line 373, in recv_strict\n    bytes_ = self.recv(min(16384, shortage))\n  File \"c:\\Users\\Sohum\\AppData\\Local\\Programs\\Python\\Python310\\lib\\site-packages\\websocket\\_core.py\", line 529, in _recv\n    return recv(self.sock, bufsize)\n  File \"c:\\Users\\Sohum\\AppData\\Local\\Programs\\Python\\Python310\\lib\\site-packages\\websocket\\_socket.py\", line 122, in recv\n    raise WebSocketConnectionClosedException(\nwebsocket._exceptions.WebSocketConnectionClosedException: Connection to remote host was lost.\n\nDuring handling of the above exception, another exception occurred:\n\nTraceback (most recent call last):\n  File \"C:\\Users\\Sohum\\AppData\\Roaming\\Python\\Python310\\site-packages\\fyers_apiv3\\FyersWebsocket\\data_ws.py\", line 1327, in __symbol_conversion\n    symbol_dict.update(symbol_dict, **symbol_value[0])\nTypeError: 'NoneType' object is not subscriptable","exception_name":"TypeError"}
{"level":"ERROR","location":"[exception:108] fyers_logger","message":"HTTPSConnectionPool(host='api-t1.fyers.in', port=443): Max retries exceeded with url: /data/quotes?symbols=NSE%3AAPOLLOHOSP-EQ%2CNSE%3ABANKBARODA-EQ%2CNSE%3ABPCL-EQ%2CNSE%3ABRITANNIA-EQ%2CNSE%3ACANBK-EQ%2CNSE%3ADIVISLAB-EQ%2CNSE%3AGRASIM-EQ%2CNSE%3AHEROMOTOCO-EQ%2CNSE%3AHINDALCO-EQ%2CNSE%3AINDUSINDBK-EQ%2CNSE%3AIOC-EQ%2CNSE%3AJSWSTEEL-EQ%2CNSE%3AONGC-EQ%2CNSE%3ARELIANCE-EQ%2CNSE%3ASBILIFE-EQ%2CNSE%3ASBIN-EQ%2CNSE%3ASHREECEM-EQ%2CNSE%3ASHRIRAMFIN-EQ%2CNSE%3ATATACONSUM-EQ%2CNSE%3ATATAMOTORS-EQ (Caused by SSLError(SSLCertVerificationError(1, '[SSL: CERTIFICATE_VERIFY_FAILED] certificate verify failed: self signed certificate in certificate chain (_ssl.c:997)')))","timestamp":"2023-11-01 13:24:35,866+0530","service":"FyersDataSocket","exception":"Traceback (most recent call last):\n  File \"c:\\Users\\Sohum\\AppData\\Local\\Programs\\Python\\Python310\\lib\\site-packages\\websocket\\_app.py\", line 412, in setSock\n    self.sock.connect(\n  File \"c:\\Users\\Sohum\\AppData\\Local\\Programs\\Python\\Python310\\lib\\site-packages\\websocket\\_core.py\", line 249, in connect\n    self.sock, addrs = connect(url, self.sock_opt, proxy_info(**options),\n  File \"c:\\Users\\Sohum\\AppData\\Local\\Programs\\Python\\Python310\\lib\\site-packages\\websocket\\_http.py\", line 136, in connect\n    sock = _ssl_socket(sock, options.sslopt, hostname)\n  File \"c:\\Users\\Sohum\\AppData\\Local\\Programs\\Python\\Python310\\lib\\site-packages\\websocket\\_http.py\", line 271, in _ssl_socket\n    sock = _wrap_sni_socket(sock, sslopt, hostname, check_hostname)\n  File \"c:\\Users\\Sohum\\AppData\\Local\\Programs\\Python\\Python310\\lib\\site-packages\\websocket\\_http.py\", line 247, in _wrap_sni_socket\n    return context.wrap_socket(\n  File \"c:\\Users\\Sohum\\AppData\\Local\\Programs\\Python\\Python310\\lib\\ssl.py\", line 513, in wrap_socket\n    return self.sslsocket_class._create(\n  File \"c:\\Users\\Sohum\\AppData\\Local\\Programs\\Python\\Python310\\lib\\ssl.py\", line 1071, in _create\n    self.do_handshake()\n  File \"c:\\Users\\Sohum\\AppData\\Local\\Programs\\Python\\Python310\\lib\\ssl.py\", line 1342, in do_handshake\n    self._sslobj.do_handshake()\nssl.SSLCertVerificationError: [SSL: CERTIFICATE_VERIFY_FAILED] certificate verify failed: self signed certificate in certificate chain (_ssl.c:997)\n\nDuring handling of the above exception, another exception occurred:\n\nTraceback (most recent call last):\n  File \"c:\\Users\\Sohum\\AppData\\Local\\Programs\\Python\\Python310\\lib\\site-packages\\urllib3\\connectionpool.py\", line 703, in urlopen\n    httplib_response = self._make_request(\n  File \"c:\\Users\\Sohum\\AppData\\Local\\Programs\\Python\\Python310\\lib\\site-packages\\urllib3\\connectionpool.py\", line 386, in _make_request\n    self._validate_conn(conn)\n  File \"c:\\Users\\Sohum\\AppData\\Local\\Programs\\Python\\Python310\\lib\\site-packages\\urllib3\\connectionpool.py\", line 1042, in _validate_conn\n    conn.connect()\n  File \"c:\\Users\\Sohum\\AppData\\Local\\Programs\\Python\\Python310\\lib\\site-packages\\urllib3\\connection.py\", line 414, in connect\n    self.sock = ssl_wrap_socket(\n  File \"c:\\Users\\Sohum\\AppData\\Local\\Programs\\Python\\Python310\\lib\\site-packages\\urllib3\\util\\ssl_.py\", line 449, in ssl_wrap_socket\n    ssl_sock = _ssl_wrap_socket_impl(\n  File \"c:\\Users\\Sohum\\AppData\\Local\\Programs\\Python\\Python310\\lib\\site-packages\\urllib3\\util\\ssl_.py\", line 493, in _ssl_wrap_socket_impl\n    return ssl_context.wrap_socket(sock, server_hostname=server_hostname)\n  File \"c:\\Users\\Sohum\\AppData\\Local\\Programs\\Python\\Python310\\lib\\ssl.py\", line 513, in wrap_socket\n    return self.sslsocket_class._create(\n  File \"c:\\Users\\Sohum\\AppData\\Local\\Programs\\Python\\Python310\\lib\\ssl.py\", line 1071, in _create\n    self.do_handshake()\n  File \"c:\\Users\\Sohum\\AppData\\Local\\Programs\\Python\\Python310\\lib\\ssl.py\", line 1342, in do_handshake\n    self._sslobj.do_handshake()\nssl.SSLCertVerificationError: [SSL: CERTIFICATE_VERIFY_FAILED] certificate verify failed: self signed certificate in certificate chain (_ssl.c:997)\n\nDuring handling of the above exception, another exception occurred:\n\nTraceback (most recent call last):\n  File \"c:\\Users\\Sohum\\AppData\\Local\\Programs\\Python\\Python310\\lib\\site-packages\\requests\\adapters.py\", line 486, in send\n    resp = conn.urlopen(\n  File \"c:\\Users\\Sohum\\AppData\\Local\\Programs\\Python\\Python310\\lib\\site-packages\\urllib3\\connectionpool.py\", line 787, in urlopen\n    retries = retries.increment(\n  File \"c:\\Users\\Sohum\\AppData\\Local\\Programs\\Python\\Python310\\lib\\site-packages\\urllib3\\util\\retry.py\", line 592, in increment\n    raise MaxRetryError(_pool, url, error or ResponseError(cause))\nurllib3.exceptions.MaxRetryError: HTTPSConnectionPool(host='api-t1.fyers.in', port=443): Max retries exceeded with url: /data/quotes?symbols=NSE%3AAPOLLOHOSP-EQ%2CNSE%3ABANKBARODA-EQ%2CNSE%3ABPCL-EQ%2CNSE%3ABRITANNIA-EQ%2CNSE%3ACANBK-EQ%2CNSE%3ADIVISLAB-EQ%2CNSE%3AGRASIM-EQ%2CNSE%3AHEROMOTOCO-EQ%2CNSE%3AHINDALCO-EQ%2CNSE%3AINDUSINDBK-EQ%2CNSE%3AIOC-EQ%2CNSE%3AJSWSTEEL-EQ%2CNSE%3AONGC-EQ%2CNSE%3ARELIANCE-EQ%2CNSE%3ASBILIFE-EQ%2CNSE%3ASBIN-EQ%2CNSE%3ASHREECEM-EQ%2CNSE%3ASHRIRAMFIN-EQ%2CNSE%3ATATACONSUM-EQ%2CNSE%3ATATAMOTORS-EQ (Caused by SSLError(SSLCertVerificationError(1, '[SSL: CERTIFICATE_VERIFY_FAILED] certificate verify failed: self signed certificate in certificate chain (_ssl.c:997)')))\n\nDuring handling of the above exception, another exception occurred:\n\nTraceback (most recent call last):\n  File \"C:\\Users\\Sohum\\AppData\\Roaming\\Python\\Python310\\site-packages\\fyers_apiv3\\FyersWebsocket\\data_ws.py\", line 65, in symbol_to_hsmtoken\n    response = requests.get(\n  File \"c:\\Users\\Sohum\\AppData\\Local\\Programs\\Python\\Python310\\lib\\site-packages\\requests\\api.py\", line 73, in get\n    return request(\"get\", url, params=params, **kwargs)\n  File \"c:\\Users\\Sohum\\AppData\\Local\\Programs\\Python\\Python310\\lib\\site-packages\\requests\\api.py\", line 59, in request\n    return session.request(method=method, url=url, **kwargs)\n  File \"c:\\Users\\Sohum\\AppData\\Local\\Programs\\Python\\Python310\\lib\\site-packages\\requests\\sessions.py\", line 589, in request\n    resp = self.send(prep, **send_kwargs)\n  File \"c:\\Users\\Sohum\\AppData\\Local\\Programs\\Python\\Python310\\lib\\site-packages\\requests\\sessions.py\", line 703, in send\n    r = adapter.send(request, **kwargs)\n  File \"c:\\Users\\Sohum\\AppData\\Local\\Programs\\Python\\Python310\\lib\\site-packages\\requests\\adapters.py\", line 517, in send\n    raise SSLError(e, request=request)\nrequests.exceptions.SSLError: HTTPSConnectionPool(host='api-t1.fyers.in', port=443): Max retries exceeded with url: /data/quotes?symbols=NSE%3AAPOLLOHOSP-EQ%2CNSE%3ABANKBARODA-EQ%2CNSE%3ABPCL-EQ%2CNSE%3ABRITANNIA-EQ%2CNSE%3ACANBK-EQ%2CNSE%3ADIVISLAB-EQ%2CNSE%3AGRASIM-EQ%2CNSE%3AHEROMOTOCO-EQ%2CNSE%3AHINDALCO-EQ%2CNSE%3AINDUSINDBK-EQ%2CNSE%3AIOC-EQ%2CNSE%3AJSWSTEEL-EQ%2CNSE%3AONGC-EQ%2CNSE%3ARELIANCE-EQ%2CNSE%3ASBILIFE-EQ%2CNSE%3ASBIN-EQ%2CNSE%3ASHREECEM-EQ%2CNSE%3ASHRIRAMFIN-EQ%2CNSE%3ATATACONSUM-EQ%2CNSE%3ATATAMOTORS-EQ (Caused by SSLError(SSLCertVerificationError(1, '[SSL: CERTIFICATE_VERIFY_FAILED] certificate verify failed: self signed certificate in certificate chain (_ssl.c:997)')))","exception_name":"SSLError"}
{"level":"ERROR","location":"[exception:108] fyers_logger","message":"'NoneType' object is not subscriptable","timestamp":"2023-11-01 13:24:35,888+0530","service":"FyersDataSocket","exception":"Traceback (most recent call last):\n  File \"c:\\Users\\Sohum\\AppData\\Local\\Programs\\Python\\Python310\\lib\\site-packages\\websocket\\_app.py\", line 412, in setSock\n    self.sock.connect(\n  File \"c:\\Users\\Sohum\\AppData\\Local\\Programs\\Python\\Python310\\lib\\site-packages\\websocket\\_core.py\", line 249, in connect\n    self.sock, addrs = connect(url, self.sock_opt, proxy_info(**options),\n  File \"c:\\Users\\Sohum\\AppData\\Local\\Programs\\Python\\Python310\\lib\\site-packages\\websocket\\_http.py\", line 136, in connect\n    sock = _ssl_socket(sock, options.sslopt, hostname)\n  File \"c:\\Users\\Sohum\\AppData\\Local\\Programs\\Python\\Python310\\lib\\site-packages\\websocket\\_http.py\", line 271, in _ssl_socket\n    sock = _wrap_sni_socket(sock, sslopt, hostname, check_hostname)\n  File \"c:\\Users\\Sohum\\AppData\\Local\\Programs\\Python\\Python310\\lib\\site-packages\\websocket\\_http.py\", line 247, in _wrap_sni_socket\n    return context.wrap_socket(\n  File \"c:\\Users\\Sohum\\AppData\\Local\\Programs\\Python\\Python310\\lib\\ssl.py\", line 513, in wrap_socket\n    return self.sslsocket_class._create(\n  File \"c:\\Users\\Sohum\\AppData\\Local\\Programs\\Python\\Python310\\lib\\ssl.py\", line 1071, in _create\n    self.do_handshake()\n  File \"c:\\Users\\Sohum\\AppData\\Local\\Programs\\Python\\Python310\\lib\\ssl.py\", line 1342, in do_handshake\n    self._sslobj.do_handshake()\nssl.SSLCertVerificationError: [SSL: CERTIFICATE_VERIFY_FAILED] certificate verify failed: self signed certificate in certificate chain (_ssl.c:997)\n\nDuring handling of the above exception, another exception occurred:\n\nTraceback (most recent call last):\n  File \"C:\\Users\\Sohum\\AppData\\Roaming\\Python\\Python310\\site-packages\\fyers_apiv3\\FyersWebsocket\\data_ws.py\", line 1327, in __symbol_conversion\n    symbol_dict.update(symbol_dict, **symbol_value[0])\nTypeError: 'NoneType' object is not subscriptable","exception_name":"TypeError"}
{"level":"ERROR","location":"[exception:108] fyers_logger","message":"HTTPSConnectionPool(host='api-t1.fyers.in', port=443): Max retries exceeded with url: /data/quotes?symbols=NSE%3AAPOLLOHOSP-EQ%2CNSE%3ABANKBARODA-EQ%2CNSE%3ABPCL-EQ%2CNSE%3ABRITANNIA-EQ%2CNSE%3ACANBK-EQ%2CNSE%3ADIVISLAB-EQ%2CNSE%3AGRASIM-EQ%2CNSE%3AHEROMOTOCO-EQ%2CNSE%3AHINDALCO-EQ%2CNSE%3AINDUSINDBK-EQ%2CNSE%3AIOC-EQ%2CNSE%3AJSWSTEEL-EQ%2CNSE%3AONGC-EQ%2CNSE%3ARELIANCE-EQ%2CNSE%3ASBILIFE-EQ%2CNSE%3ASBIN-EQ%2CNSE%3ASHREECEM-EQ%2CNSE%3ASHRIRAMFIN-EQ%2CNSE%3ATATACONSUM-EQ%2CNSE%3ATATAMOTORS-EQ (Caused by SSLError(SSLCertVerificationError(1, '[SSL: CERTIFICATE_VERIFY_FAILED] certificate verify failed: self signed certificate in certificate chain (_ssl.c:997)')))","timestamp":"2023-11-01 13:24:40,899+0530","service":"FyersDataSocket","exception":"Traceback (most recent call last):\n  File \"c:\\Users\\Sohum\\AppData\\Local\\Programs\\Python\\Python310\\lib\\site-packages\\websocket\\_app.py\", line 412, in setSock\n    self.sock.connect(\n  File \"c:\\Users\\Sohum\\AppData\\Local\\Programs\\Python\\Python310\\lib\\site-packages\\websocket\\_core.py\", line 249, in connect\n    self.sock, addrs = connect(url, self.sock_opt, proxy_info(**options),\n  File \"c:\\Users\\Sohum\\AppData\\Local\\Programs\\Python\\Python310\\lib\\site-packages\\websocket\\_http.py\", line 136, in connect\n    sock = _ssl_socket(sock, options.sslopt, hostname)\n  File \"c:\\Users\\Sohum\\AppData\\Local\\Programs\\Python\\Python310\\lib\\site-packages\\websocket\\_http.py\", line 271, in _ssl_socket\n    sock = _wrap_sni_socket(sock, sslopt, hostname, check_hostname)\n  File \"c:\\Users\\Sohum\\AppData\\Local\\Programs\\Python\\Python310\\lib\\site-packages\\websocket\\_http.py\", line 247, in _wrap_sni_socket\n    return context.wrap_socket(\n  File \"c:\\Users\\Sohum\\AppData\\Local\\Programs\\Python\\Python310\\lib\\ssl.py\", line 513, in wrap_socket\n    return self.sslsocket_class._create(\n  File \"c:\\Users\\Sohum\\AppData\\Local\\Programs\\Python\\Python310\\lib\\ssl.py\", line 1071, in _create\n    self.do_handshake()\n  File \"c:\\Users\\Sohum\\AppData\\Local\\Programs\\Python\\Python310\\lib\\ssl.py\", line 1342, in do_handshake\n    self._sslobj.do_handshake()\nssl.SSLCertVerificationError: [SSL: CERTIFICATE_VERIFY_FAILED] certificate verify failed: self signed certificate in certificate chain (_ssl.c:997)\n\nDuring handling of the above exception, another exception occurred:\n\nTraceback (most recent call last):\n  File \"c:\\Users\\Sohum\\AppData\\Local\\Programs\\Python\\Python310\\lib\\site-packages\\urllib3\\connectionpool.py\", line 703, in urlopen\n    httplib_response = self._make_request(\n  File \"c:\\Users\\Sohum\\AppData\\Local\\Programs\\Python\\Python310\\lib\\site-packages\\urllib3\\connectionpool.py\", line 386, in _make_request\n    self._validate_conn(conn)\n  File \"c:\\Users\\Sohum\\AppData\\Local\\Programs\\Python\\Python310\\lib\\site-packages\\urllib3\\connectionpool.py\", line 1042, in _validate_conn\n    conn.connect()\n  File \"c:\\Users\\Sohum\\AppData\\Local\\Programs\\Python\\Python310\\lib\\site-packages\\urllib3\\connection.py\", line 414, in connect\n    self.sock = ssl_wrap_socket(\n  File \"c:\\Users\\Sohum\\AppData\\Local\\Programs\\Python\\Python310\\lib\\site-packages\\urllib3\\util\\ssl_.py\", line 449, in ssl_wrap_socket\n    ssl_sock = _ssl_wrap_socket_impl(\n  File \"c:\\Users\\Sohum\\AppData\\Local\\Programs\\Python\\Python310\\lib\\site-packages\\urllib3\\util\\ssl_.py\", line 493, in _ssl_wrap_socket_impl\n    return ssl_context.wrap_socket(sock, server_hostname=server_hostname)\n  File \"c:\\Users\\Sohum\\AppData\\Local\\Programs\\Python\\Python310\\lib\\ssl.py\", line 513, in wrap_socket\n    return self.sslsocket_class._create(\n  File \"c:\\Users\\Sohum\\AppData\\Local\\Programs\\Python\\Python310\\lib\\ssl.py\", line 1071, in _create\n    self.do_handshake()\n  File \"c:\\Users\\Sohum\\AppData\\Local\\Programs\\Python\\Python310\\lib\\ssl.py\", line 1342, in do_handshake\n    self._sslobj.do_handshake()\nssl.SSLCertVerificationError: [SSL: CERTIFICATE_VERIFY_FAILED] certificate verify failed: self signed certificate in certificate chain (_ssl.c:997)\n\nDuring handling of the above exception, another exception occurred:\n\nTraceback (most recent call last):\n  File \"c:\\Users\\Sohum\\AppData\\Local\\Programs\\Python\\Python310\\lib\\site-packages\\requests\\adapters.py\", line 486, in send\n    resp = conn.urlopen(\n  File \"c:\\Users\\Sohum\\AppData\\Local\\Programs\\Python\\Python310\\lib\\site-packages\\urllib3\\connectionpool.py\", line 787, in urlopen\n    retries = retries.increment(\n  File \"c:\\Users\\Sohum\\AppData\\Local\\Programs\\Python\\Python310\\lib\\site-packages\\urllib3\\util\\retry.py\", line 592, in increment\n    raise MaxRetryError(_pool, url, error or ResponseError(cause))\nurllib3.exceptions.MaxRetryError: HTTPSConnectionPool(host='api-t1.fyers.in', port=443): Max retries exceeded with url: /data/quotes?symbols=NSE%3AAPOLLOHOSP-EQ%2CNSE%3ABANKBARODA-EQ%2CNSE%3ABPCL-EQ%2CNSE%3ABRITANNIA-EQ%2CNSE%3ACANBK-EQ%2CNSE%3ADIVISLAB-EQ%2CNSE%3AGRASIM-EQ%2CNSE%3AHEROMOTOCO-EQ%2CNSE%3AHINDALCO-EQ%2CNSE%3AINDUSINDBK-EQ%2CNSE%3AIOC-EQ%2CNSE%3AJSWSTEEL-EQ%2CNSE%3AONGC-EQ%2CNSE%3ARELIANCE-EQ%2CNSE%3ASBILIFE-EQ%2CNSE%3ASBIN-EQ%2CNSE%3ASHREECEM-EQ%2CNSE%3ASHRIRAMFIN-EQ%2CNSE%3ATATACONSUM-EQ%2CNSE%3ATATAMOTORS-EQ (Caused by SSLError(SSLCertVerificationError(1, '[SSL: CERTIFICATE_VERIFY_FAILED] certificate verify failed: self signed certificate in certificate chain (_ssl.c:997)')))\n\nDuring handling of the above exception, another exception occurred:\n\nTraceback (most recent call last):\n  File \"C:\\Users\\Sohum\\AppData\\Roaming\\Python\\Python310\\site-packages\\fyers_apiv3\\FyersWebsocket\\data_ws.py\", line 65, in symbol_to_hsmtoken\n    response = requests.get(\n  File \"c:\\Users\\Sohum\\AppData\\Local\\Programs\\Python\\Python310\\lib\\site-packages\\requests\\api.py\", line 73, in get\n    return request(\"get\", url, params=params, **kwargs)\n  File \"c:\\Users\\Sohum\\AppData\\Local\\Programs\\Python\\Python310\\lib\\site-packages\\requests\\api.py\", line 59, in request\n    return session.request(method=method, url=url, **kwargs)\n  File \"c:\\Users\\Sohum\\AppData\\Local\\Programs\\Python\\Python310\\lib\\site-packages\\requests\\sessions.py\", line 589, in request\n    resp = self.send(prep, **send_kwargs)\n  File \"c:\\Users\\Sohum\\AppData\\Local\\Programs\\Python\\Python310\\lib\\site-packages\\requests\\sessions.py\", line 703, in send\n    r = adapter.send(request, **kwargs)\n  File \"c:\\Users\\Sohum\\AppData\\Local\\Programs\\Python\\Python310\\lib\\site-packages\\requests\\adapters.py\", line 517, in send\n    raise SSLError(e, request=request)\nrequests.exceptions.SSLError: HTTPSConnectionPool(host='api-t1.fyers.in', port=443): Max retries exceeded with url: /data/quotes?symbols=NSE%3AAPOLLOHOSP-EQ%2CNSE%3ABANKBARODA-EQ%2CNSE%3ABPCL-EQ%2CNSE%3ABRITANNIA-EQ%2CNSE%3ACANBK-EQ%2CNSE%3ADIVISLAB-EQ%2CNSE%3AGRASIM-EQ%2CNSE%3AHEROMOTOCO-EQ%2CNSE%3AHINDALCO-EQ%2CNSE%3AINDUSINDBK-EQ%2CNSE%3AIOC-EQ%2CNSE%3AJSWSTEEL-EQ%2CNSE%3AONGC-EQ%2CNSE%3ARELIANCE-EQ%2CNSE%3ASBILIFE-EQ%2CNSE%3ASBIN-EQ%2CNSE%3ASHREECEM-EQ%2CNSE%3ASHRIRAMFIN-EQ%2CNSE%3ATATACONSUM-EQ%2CNSE%3ATATAMOTORS-EQ (Caused by SSLError(SSLCertVerificationError(1, '[SSL: CERTIFICATE_VERIFY_FAILED] certificate verify failed: self signed certificate in certificate chain (_ssl.c:997)')))","exception_name":"SSLError"}
{"level":"ERROR","location":"[exception:108] fyers_logger","message":"'NoneType' object is not subscriptable","timestamp":"2023-11-01 13:24:40,905+0530","service":"FyersDataSocket","exception":"Traceback (most recent call last):\n  File \"c:\\Users\\Sohum\\AppData\\Local\\Programs\\Python\\Python310\\lib\\site-packages\\websocket\\_app.py\", line 412, in setSock\n    self.sock.connect(\n  File \"c:\\Users\\Sohum\\AppData\\Local\\Programs\\Python\\Python310\\lib\\site-packages\\websocket\\_core.py\", line 249, in connect\n    self.sock, addrs = connect(url, self.sock_opt, proxy_info(**options),\n  File \"c:\\Users\\Sohum\\AppData\\Local\\Programs\\Python\\Python310\\lib\\site-packages\\websocket\\_http.py\", line 136, in connect\n    sock = _ssl_socket(sock, options.sslopt, hostname)\n  File \"c:\\Users\\Sohum\\AppData\\Local\\Programs\\Python\\Python310\\lib\\site-packages\\websocket\\_http.py\", line 271, in _ssl_socket\n    sock = _wrap_sni_socket(sock, sslopt, hostname, check_hostname)\n  File \"c:\\Users\\Sohum\\AppData\\Local\\Programs\\Python\\Python310\\lib\\site-packages\\websocket\\_http.py\", line 247, in _wrap_sni_socket\n    return context.wrap_socket(\n  File \"c:\\Users\\Sohum\\AppData\\Local\\Programs\\Python\\Python310\\lib\\ssl.py\", line 513, in wrap_socket\n    return self.sslsocket_class._create(\n  File \"c:\\Users\\Sohum\\AppData\\Local\\Programs\\Python\\Python310\\lib\\ssl.py\", line 1071, in _create\n    self.do_handshake()\n  File \"c:\\Users\\Sohum\\AppData\\Local\\Programs\\Python\\Python310\\lib\\ssl.py\", line 1342, in do_handshake\n    self._sslobj.do_handshake()\nssl.SSLCertVerificationError: [SSL: CERTIFICATE_VERIFY_FAILED] certificate verify failed: self signed certificate in certificate chain (_ssl.c:997)\n\nDuring handling of the above exception, another exception occurred:\n\nTraceback (most recent call last):\n  File \"C:\\Users\\Sohum\\AppData\\Roaming\\Python\\Python310\\site-packages\\fyers_apiv3\\FyersWebsocket\\data_ws.py\", line 1327, in __symbol_conversion\n    symbol_dict.update(symbol_dict, **symbol_value[0])\nTypeError: 'NoneType' object is not subscriptable","exception_name":"TypeError"}
